Workbook

Sheet All Cases - Enter Cases
A1: S.No | B1: Target Name | C1: Target Category | D1: Target Address | E1: City | F1: Provence | G1: Client | H1: Brand Name | I1: Product Name | J1: Case Submission Date | K1: Case Status | L1: Status Date | M1: Remarks
A2: 1 | B2: Marfani Traders | C2: Shop | D2: Godown No. S-19 West Warf, New Lipton Gali ,Karachi | E2: Karachi | F2: Sindh | G2: OneWorld | H2: Wd-40 | I2: Fluid | J2: 45966 | K2: Approved | L2: 46003
A3: 2 | B3: Sami Garments Factory | C3: Factory | D3: Plot No.L-27 Sector 12B Industrial Area ,New Karachi | E3: Karachi | F3: Sindh | G3: SafeMark | H3: Reebok | I3: Garments | J3: 46031 | K3: Approved | L3: 46035
A4: 3 | B4: Sami Garments Factory | C4: Factory | D4: Plot No.L-27 Sector 12B Industrial Area ,New Karachi | E4: Karachi | F4: Sindh | G4: SafeMark | H4: Champion | I4: Garments | J4: 46031 | K4: Approved | L4: 46035
A5: 4 | B5: Sami Garments Factory | C5: Factory | D5: Plot No.L-27 Sector 12B Industrial Area ,New Karachi | E5: Karachi | F5: Sindh | G5: SafeMark | H5: Hugo Boss | I5: Garments | J5: 46031 | K5: Approved | L5: 46035
A6: 5 | B6: Faisal Shoes Manufacturing | C6: Factory | D6: Plot No.C-62 Taksali Androne Lahore | E6: Lahore | F6: Punjab | G6: SafeMark | H6: Tommy Hilfiger | I6: Shoes | J6: 46031 | K6: Approved | L6: 46039
A7: 6 | B7: Faisal Shoes Manufacturing | C7: Factory | D7: Plot No.C-62 Taksali Androne Lahore | E7: Lahore | F7: Punjab | G7: SafeMark | H7: Calvin Klein | I7: Shoes | J7: 46031 | K7: Approved | L7: 46040
A8: 7 | B8: Faisal Shoes Manufacturing | C8: Factory | D8: Plot No.C-62 Taksali Androne Lahore | E8: Lahore | F8: Punjab | G8: SafeMark | H8: Reebok | I8: Shoes | J8: 46027 | K8: Approved | L8: 46029
A9: 8 | B9: Faisal Shoes Manufacturing | C9: Factory | D9: Plot No.C-62 Taksali Androne Lahore | E9: Lahore | F9: Punjab | G9: AA | H9: Gucci | I9: Shoes | J9: 46029 | K9: Approved | L9: 46041
A10: 9 | B10: Faisal Shoes Manufacturing | C10: Factory | D10: Plot No.C-62 Taksali Androne Lahore | E10: Lahore | F10: Punjab | G10: SafeMark | H10: New Balance | I10: Shoes | J10: 46027 | K10: Approved | L10: 46029
A11: 10 | B11: Faisal Shoes Manufacturing | C11: Factory | D11: Plot No.C-62 Taksali Androne Lahore | E11: Lahore | F11: Punjab | G11: SafeMark | H11: Hugo Boss | I11: Shoes | J11: 46027 | K11: Approved | L11: 46029
A12: 11 | B12: A.K Jeans | C12: WholeSale | D12: Shop No.79, Al karim Market , New Anarkali ,Lahore | E12: Lahore | F12: Punjab | G12: SafeMark | H12: Tommy Hilfiger | I12: Jeans | J12: 46031 | K12: Approved | L12: 46045
A13: 12 | B13: A.K Jeans | C13: WholeSale | D13: Shop No.79, Al karim Market , New Anarkali ,Lahore | E13: Lahore | F13: Punjab | G13: SafeMark | H13: Levis | I13: Jeans | J13: 46031 | K13: Approved | L13: 46038
A14: 13 | B14: A.K Jeans | C14: WholeSale | D14: Shop No.79, Al karim Market , New Anarkali ,Lahore | E14: Lahore | F14: Punjab | G14: SafeMark | H14: Guess | I14: Jeans | J14: 46031 | K14: Rejected
A15: 14 | B15: Scarf Case | C15: Customs | D15: Mugal Pura dry port Lahore | E15: Lahore | F15: Punjab | G15: AA | H15: Gucci | I15: scarf | J15: 45975 | K15: Approved | L15: 46035
A16: 15 | B16: kashif Printing | C16: Distributor | D16: Plot No.D-43 Androne lahore | E16: Lahore | F16: Punjab | G16: OneWorld | H16: Wd-40 | I16: Fluid | J16: 45824 | K16: Approved | L16: 46193

Sheet Sindh
A1: S.No | B1: Target Name | C1: Target Category | D1: Target Address | E1: City | F1: Provence | G1: Client | H1: Brand Name | I1: Product Name | J1: Case Submission Date | K1: Case Status | L1: Status Date | M1: Remarks
A2: =IF('All Cases - Enter Cases'!$F2="Sindh",'All Cases - Enter Cases'!A2,"") -> 1 | B2: =IF($A2<>"",'All Cases - Enter Cases'!B2,"") -> Marfani Traders | C2: =IF($A2<>"",'All Cases - Enter Cases'!C2,"") -> Shop | D2: =IF($A2<>"",'All Cases - Enter Cases'!D2,"") -> Godown No. S-19 West Warf, New Lipton Gali ,Karachi | E2: =IF($A2<>"",'All Cases - Enter Cases'!E2,"") -> Karachi | F2: =IF($A2<>"",'All Cases - Enter Cases'!F2,"") -> Sindh | G2: =IF($A2<>"",'All Cases - Enter Cases'!G2,"") -> OneWorld | H2: =IF($A2<>"",'All Cases - Enter Cases'!H2,"") -> Wd-40 | I2: =IF($A2<>"",'All Cases - Enter Cases'!I2,"") -> Fluid | ... M2: =IF($A2<>"",'All Cases - Enter Cases'!M2,"") -> 0
A3: =IF('All Cases - Enter Cases'!$F3="Sindh",'All Cases - Enter Cases'!A3,"") -> 2 | B3: =IF($A3<>"",'All Cases - Enter Cases'!B3,"") -> Sami Garments Factory | C3: =IF($A3<>"",'All Cases - Enter Cases'!C3,"") -> Factory | D3: =IF($A3<>"",'All Cases - Enter Cases'!D3,"") -> Plot No.L-27 Sector 12B Industrial Area ,New Karachi | E3: =IF($A3<>"",'All Cases - Enter Cases'!E3,"") -> Karachi | F3: =IF($A3<>"",'All Cases - Enter Cases'!F3,"") -> Sindh | G3: =IF($A3<>"",'All Cases - Enter Cases'!G3,"") -> SafeMark | H3: =IF($A3<>"",'All Cases - Enter Cases'!H3,"") -> Reebok | I3: =IF($A3<>"",'All Cases - Enter Cases'!I3,"") -> Garments | ... M3: =IF($A3<>"",'All Cases - Enter Cases'!M3,"") -> 0
A4: =IF('All Cases - Enter Cases'!$F4="Sindh",'All Cases - Enter Cases'!A4,"") -> 3 | B4: =IF($A4<>"",'All Cases - Enter Cases'!B4,"") -> Sami Garments Factory | C4: =IF($A4<>"",'All Cases - Enter Cases'!C4,"") -> Factory | D4: =IF($A4<>"",'All Cases - Enter Cases'!D4,"") -> Plot No.L-27 Sector 12B Industrial Area ,New Karachi | E4: =IF($A4<>"",'All Cases - Enter Cases'!E4,"") -> Karachi | F4: =IF($A4<>"",'All Cases - Enter Cases'!F4,"") -> Sindh | G4: =IF($A4<>"",'All Cases - Enter Cases'!G4,"") -> SafeMark | H4: =IF($A4<>"",'All Cases - Enter Cases'!H4,"") -> Champion | I4: =IF($A4<>"",'All Cases - Enter Cases'!I4,"") -> Garments | ... M4: =IF($A4<>"",'All Cases - Enter Cases'!M4,"") -> 0
A5: =IF('All Cases - Enter Cases'!$F5="Sindh",'All Cases - Enter Cases'!A5,"") -> 4 | B5: =IF($A5<>"",'All Cases - Enter Cases'!B5,"") -> Sami Garments Factory | C5: =IF($A5<>"",'All Cases - Enter Cases'!C5,"") -> Factory | D5: =IF($A5<>"",'All Cases - Enter Cases'!D5,"") -> Plot No.L-27 Sector 12B Industrial Area ,New Karachi | E5: =IF($A5<>"",'All Cases - Enter Cases'!E5,"") -> Karachi | F5: =IF($A5<>"",'All Cases - Enter Cases'!F5,"") -> Sindh | G5: =IF($A5<>"",'All Cases - Enter Cases'!G5,"") -> SafeMark | H5: =IF($A5<>"",'All Cases - Enter Cases'!H5,"") -> Hugo Boss | I5: =IF($A5<>"",'All Cases - Enter Cases'!I5,"") -> Garments | ... M5: =IF($A5<>"",'All Cases - Enter Cases'!M5,"") -> 0
A6: =IF('All Cases - Enter Cases'!$F6="Sindh",'All Cases - Enter Cases'!A6,"") | B6: =IF($A6<>"",'All Cases - Enter Cases'!B6,"") | C6: =IF($A6<>"",'All Cases - Enter Cases'!C6,"") | D6: =IF($A6<>"",'All Cases - Enter Cases'!D6,"") | E6: =IF($A6<>"",'All Cases - Enter Cases'!E6,"") | F6: =IF($A6<>"",'All Cases - Enter Cases'!F6,"") | G6: =IF($A6<>"",'All Cases - Enter Cases'!G6,"") | H6: =IF($A6<>"",'All Cases - Enter Cases'!H6,"") | I6: =IF($A6<>"",'All Cases - Enter Cases'!I6,"") | ... M6: =IF($A6<>"",'All Cases - Enter Cases'!M6,"")
A7: =IF('All Cases - Enter Cases'!$F7="Sindh",'All Cases - Enter Cases'!A7,"") | B7: =IF($A7<>"",'All Cases - Enter Cases'!B7,"") | C7: =IF($A7<>"",'All Cases - Enter Cases'!C7,"") | D7: =IF($A7<>"",'All Cases - Enter Cases'!D7,"") | E7: =IF($A7<>"",'All Cases - Enter Cases'!E7,"") | F7: =IF($A7<>"",'All Cases - Enter Cases'!F7,"") | G7: =IF($A7<>"",'All Cases - Enter Cases'!G7,"") | H7: =IF($A7<>"",'All Cases - Enter Cases'!H7,"") | I7: =IF($A7<>"",'All Cases - Enter Cases'!I7,"") | ... M7: =IF($A7<>"",'All Cases - Enter Cases'!M7,"")
A8: =IF('All Cases - Enter Cases'!$F8="Sindh",'All Cases - Enter Cases'!A8,"") | B8: =IF($A8<>"",'All Cases - Enter Cases'!B8,"") | C8: =IF($A8<>"",'All Cases - Enter Cases'!C8,"") | D8: =IF($A8<>"",'All Cases - Enter Cases'!D8,"") | E8: =IF($A8<>"",'All Cases - Enter Cases'!E8,"") | F8: =IF($A8<>"",'All Cases - Enter Cases'!F8,"") | G8: =IF($A8<>"",'All Cases - Enter Cases'!G8,"") | H8: =IF($A8<>"",'All Cases - Enter Cases'!H8,"") | I8: =IF($A8<>"",'All Cases - Enter Cases'!I8,"") | ... M8: =IF($A8<>"",'All Cases - Enter Cases'!M8,"")
A9: =IF('All Cases - Enter Cases'!$F9="Sindh",'All Cases - Enter Cases'!A9,"") | B9: =IF($A9<>"",'All Cases - Enter Cases'!B9,"") | C9: =IF($A9<>"",'All Cases - Enter Cases'!C9,"") | D9: =IF($A9<>"",'All Cases - Enter Cases'!D9,"") | E9: =IF($A9<>"",'All Cases - Enter Cases'!E9,"") | F9: =IF($A9<>"",'All Cases - Enter Cases'!F9,"") | G9: =IF($A9<>"",'All Cases - Enter Cases'!G9,"") | H9: =IF($A9<>"",'All Cases - Enter Cases'!H9,"") | I9: =IF($A9<>"",'All Cases - Enter Cases'!I9,"") | ... M9: =IF($A9<>"",'All Cases - Enter Cases'!M9,"")
A10: =IF('All Cases - Enter Cases'!$F10="Sindh",'All Cases - Enter Cases'!A10,"") | B10: =IF($A10<>"",'All Cases - Enter Cases'!B10,"") | C10: =IF($A10<>"",'All Cases - Enter Cases'!C10,"") | D10: =IF($A10<>"",'All Cases - Enter Cases'!D10,"") | E10: =IF($A10<>"",'All Cases - Enter Cases'!E10,"") | F10: =IF($A10<>"",'All Cases - Enter Cases'!F10,"") | G10: =IF($A10<>"",'All Cases - Enter Cases'!G10,"") | H10: =IF($A10<>"",'All Cases - Enter Cases'!H10,"") | I10: =IF($A10<>"",'All Cases - Enter Cases'!I10,"") | ... M10: =IF($A10<>"",'All Cases - Enter Cases'!M10,"")
A11: =IF('All Cases - Enter Cases'!$F11="Sindh",'All Cases - Enter Cases'!A11,"") | B11: =IF($A11<>"",'All Cases - Enter Cases'!B11,"") | C11: =IF($A11<>"",'All Cases - Enter Cases'!C11,"") | D11: =IF($A11<>"",'All Cases - Enter Cases'!D11,"") | E11: =IF($A11<>"",'All Cases - Enter Cases'!E11,"") | F11: =IF($A11<>"",'All Cases - Enter Cases'!F11,"") | G11: =IF($A11<>"",'All Cases - Enter Cases'!G11,"") | H11: =IF($A11<>"",'All Cases - Enter Cases'!H11,"") | I11: =IF($A11<>"",'All Cases - Enter Cases'!I11,"") | ... M11: =IF($A11<>"",'All Cases - Enter Cases'!M11,"")
A12: =IF('All Cases - Enter Cases'!$F12="Sindh",'All Cases - Enter Cases'!A12,"") | B12: =IF($A12<>"",'All Cases - Enter Cases'!B12,"") | C12: =IF($A12<>"",'All Cases - Enter Cases'!C12,"") | D12: =IF($A12<>"",'All Cases - Enter Cases'!D12,"") | E12: =IF($A12<>"",'All Cases - Enter Cases'!E12,"") | F12: =IF($A12<>"",'All Cases - Enter Cases'!F12,"") | G12: =IF($A12<>"",'All Cases - Enter Cases'!G12,"") | H12: =IF($A12<>"",'All Cases - Enter Cases'!H12,"") | I12: =IF($A12<>"",'All Cases - Enter Cases'!I12,"") | ... M12: =IF($A12<>"",'All Cases - Enter Cases'!M12,"")
A13: =IF('All Cases - Enter Cases'!$F13="Sindh",'All Cases - Enter Cases'!A13,"") | B13: =IF($A13<>"",'All Cases - Enter Cases'!B13,"") | C13: =IF($A13<>"",'All Cases - Enter Cases'!C13,"") | D13: =IF($A13<>"",'All Cases - Enter Cases'!D13,"") | E13: =IF($A13<>"",'All Cases - Enter Cases'!E13,"") | F13: =IF($A13<>"",'All Cases - Enter Cases'!F13,"") | G13: =IF($A13<>"",'All Cases - Enter Cases'!G13,"") | H13: =IF($A13<>"",'All Cases - Enter Cases'!H13,"") | I13: =IF($A13<>"",'All Cases - Enter Cases'!I13,"") | ... M13: =IF($A13<>"",'All Cases - Enter Cases'!M13,"")
... A1000: =IF('All Cases - Enter Cases'!$F1000="Sindh",'All Cases - Enter Cases'!A1000,"") | B1000: =IF($A1000<>"",'All Cases - Enter Cases'!B1000,"") | C1000: =IF($A1000<>"",'All Cases - Enter Cases'!C1000,"") | D1000: =IF($A1000<>"",'All Cases - Enter Cases'!D1000,"") | E1000: =IF($A1000<>"",'All Cases - Enter Cases'!E1000,"") | F1000: =IF($A1000<>"",'All Cases - Enter Cases'!F1000,"") | G1000: =IF($A1000<>"",'All Cases - Enter Cases'!G1000,"") | H1000: =IF($A1000<>"",'All Cases - Enter Cases'!H1000,"") | I1000: =IF($A1000<>"",'All Cases - Enter Cases'!I1000,"") | ... M1000: =IF($A1000<>"",'All Cases - Enter Cases'!M1000,"")

Sheet Punjab
A1: S.No | B1: Target Name | C1: Target Category | D1: Target Address | E1: City | F1: Provence | G1: Client | H1: Brand Name | I1: Product Name | J1: Case Submission Date | K1: Case Status | L1: Status Date | M1: Remarks
A2: =IF('All Cases - Enter Cases'!$F2="Punjab",'All Cases - Enter Cases'!A2,"") | B2: =IF($A2<>"",'All Cases - Enter Cases'!B2,"") | C2: =IF($A2<>"",'All Cases - Enter Cases'!C2,"") | D2: =IF($A2<>"",'All Cases - Enter Cases'!D2,"") | E2: =IF($A2<>"",'All Cases - Enter Cases'!E2,"") | F2: =IF($A2<>"",'All Cases - Enter Cases'!F2,"") | G2: =IF($A2<>"",'All Cases - Enter Cases'!G2,"") | H2: =IF($A2<>"",'All Cases - Enter Cases'!H2,"") | I2: =IF($A2<>"",'All Cases - Enter Cases'!I2,"") | ... M2: =IF($A2<>"",'All Cases - Enter Cases'!M2,"")
A3: =IF('All Cases - Enter Cases'!$F3="Punjab",'All Cases - Enter Cases'!A3,"") | B3: =IF($A3<>"",'All Cases - Enter Cases'!B3,"") | C3: =IF($A3<>"",'All Cases - Enter Cases'!C3,"") | D3: =IF($A3<>"",'All Cases - Enter Cases'!D3,"") | E3: =IF($A3<>"",'All Cases - Enter Cases'!E3,"") | F3: =IF($A3<>"",'All Cases - Enter Cases'!F3,"") | G3: =IF($A3<>"",'All Cases - Enter Cases'!G3,"") | H3: =IF($A3<>"",'All Cases - Enter Cases'!H3,"") | I3: =IF($A3<>"",'All Cases - Enter Cases'!I3,"") | ... M3: =IF($A3<>"",'All Cases - Enter Cases'!M3,"")
A4: =IF('All Cases - Enter Cases'!$F4="Punjab",'All Cases - Enter Cases'!A4,"") | B4: =IF($A4<>"",'All Cases - Enter Cases'!B4,"") | C4: =IF($A4<>"",'All Cases - Enter Cases'!C4,"") | D4: =IF($A4<>"",'All Cases - Enter Cases'!D4,"") | E4: =IF($A4<>"",'All Cases - Enter Cases'!E4,"") | F4: =IF($A4<>"",'All Cases - Enter Cases'!F4,"") | G4: =IF($A4<>"",'All Cases - Enter Cases'!G4,"") | H4: =IF($A4<>"",'All Cases - Enter Cases'!H4,"") | I4: =IF($A4<>"",'All Cases - Enter Cases'!I4,"") | ... M4: =IF($A4<>"",'All Cases - Enter Cases'!M4,"")
A5: =IF('All Cases - Enter Cases'!$F5="Punjab",'All Cases - Enter Cases'!A5,"") | B5: =IF($A5<>"",'All Cases - Enter Cases'!B5,"") | C5: =IF($A5<>"",'All Cases - Enter Cases'!C5,"") | D5: =IF($A5<>"",'All Cases - Enter Cases'!D5,"") | E5: =IF($A5<>"",'All Cases - Enter Cases'!E5,"") | F5: =IF($A5<>"",'All Cases - Enter Cases'!F5,"") | G5: =IF($A5<>"",'All Cases - Enter Cases'!G5,"") | H5: =IF($A5<>"",'All Cases - Enter Cases'!H5,"") | I5: =IF($A5<>"",'All Cases - Enter Cases'!I5,"") | ... M5: =IF($A5<>"",'All Cases - Enter Cases'!M5,"")
A6: =IF('All Cases - Enter Cases'!$F6="Punjab",'All Cases - Enter Cases'!A6,"") -> 5 | B6: =IF($A6<>"",'All Cases - Enter Cases'!B6,"") -> Faisal Shoes Manufacturing | C6: =IF($A6<>"",'All Cases - Enter Cases'!C6,"") -> Factory | D6: =IF($A6<>"",'All Cases - Enter Cases'!D6,"") -> Plot No.C-62 Taksali Androne Lahore | E6: =IF($A6<>"",'All Cases - Enter Cases'!E6,"") -> Lahore | F6: =IF($A6<>"",'All Cases - Enter Cases'!F6,"") -> Punjab | G6: =IF($A6<>"",'All Cases - Enter Cases'!G6,"") -> SafeMark | H6: =IF($A6<>"",'All Cases - Enter Cases'!H6,"") -> Tommy Hilfiger | I6: =IF($A6<>"",'All Cases - Enter Cases'!I6,"") -> Shoes | ... M6: =IF($A6<>"",'All Cases - Enter Cases'!M6,"") -> 0
A7: =IF('All Cases - Enter Cases'!$F7="Punjab",'All Cases - Enter Cases'!A7,"") -> 6 | B7: =IF($A7<>"",'All Cases - Enter Cases'!B7,"") -> Faisal Shoes Manufacturing | C7: =IF($A7<>"",'All Cases - Enter Cases'!C7,"") -> Factory | D7: =IF($A7<>"",'All Cases - Enter Cases'!D7,"") -> Plot No.C-62 Taksali Androne Lahore | E7: =IF($A7<>"",'All Cases - Enter Cases'!E7,"") -> Lahore | F7: =IF($A7<>"",'All Cases - Enter Cases'!F7,"") -> Punjab | G7: =IF($A7<>"",'All Cases - Enter Cases'!G7,"") -> SafeMark | H7: =IF($A7<>"",'All Cases - Enter Cases'!H7,"") -> Calvin Klein | I7: =IF($A7<>"",'All Cases - Enter Cases'!I7,"") -> Shoes | ... M7: =IF($A7<>"",'All Cases - Enter Cases'!M7,"") -> 0
A8: =IF('All Cases - Enter Cases'!$F8="Punjab",'All Cases - Enter Cases'!A8,"") -> 7 | B8: =IF($A8<>"",'All Cases - Enter Cases'!B8,"") -> Faisal Shoes Manufacturing | C8: =IF($A8<>"",'All Cases - Enter Cases'!C8,"") -> Factory | D8: =IF($A8<>"",'All Cases - Enter Cases'!D8,"") -> Plot No.C-62 Taksali Androne Lahore | E8: =IF($A8<>"",'All Cases - Enter Cases'!E8,"") -> Lahore | F8: =IF($A8<>"",'All Cases - Enter Cases'!F8,"") -> Punjab | G8: =IF($A8<>"",'All Cases - Enter Cases'!G8,"") -> SafeMark | H8: =IF($A8<>"",'All Cases - Enter Cases'!H8,"") -> Reebok | I8: =IF($A8<>"",'All Cases - Enter Cases'!I8,"") -> Shoes | ... M8: =IF($A8<>"",'All Cases - Enter Cases'!M8,"") -> 0
A9: =IF('All Cases - Enter Cases'!$F9="Punjab",'All Cases - Enter Cases'!A9,"") -> 8 | B9: =IF($A9<>"",'All Cases - Enter Cases'!B9,"") -> Faisal Shoes Manufacturing | C9: =IF($A9<>"",'All Cases - Enter Cases'!C9,"") -> Factory | D9: =IF($A9<>"",'All Cases - Enter Cases'!D9,"") -> Plot No.C-62 Taksali Androne Lahore | E9: =IF($A9<>"",'All Cases - Enter Cases'!E9,"") -> Lahore | F9: =IF($A9<>"",'All Cases - Enter Cases'!F9,"") -> Punjab | G9: =IF($A9<>"",'All Cases - Enter Cases'!G9,"") -> AA | H9: =IF($A9<>"",'All Cases - Enter Cases'!H9,"") -> Gucci | I9: =IF($A9<>"",'All Cases - Enter Cases'!I9,"") -> Shoes | ... M9: =IF($A9<>"",'All Cases - Enter Cases'!M9,"") -> 0
A10: =IF('All Cases - Enter Cases'!$F10="Punjab",'All Cases - Enter Cases'!A10,"") -> 9 | B10: =IF($A10<>"",'All Cases - Enter Cases'!B10,"") -> Faisal Shoes Manufacturing | C10: =IF($A10<>"",'All Cases - Enter Cases'!C10,"") -> Factory | D10: =IF($A10<>"",'All Cases - Enter Cases'!D10,"") -> Plot No.C-62 Taksali Androne Lahore | E10: =IF($A10<>"",'All Cases - Enter Cases'!E10,"") -> Lahore | F10: =IF($A10<>"",'All Cases - Enter Cases'!F10,"") -> Punjab | G10: =IF($A10<>"",'All Cases - Enter Cases'!G10,"") -> SafeMark | H10: =IF($A10<>"",'All Cases - Enter Cases'!H10,"") -> New Balance | I10: =IF($A10<>"",'All Cases - Enter Cases'!I10,"") -> Shoes | ... M10: =IF($A10<>"",'All Cases - Enter Cases'!M10,"") -> 0
A11: =IF('All Cases - Enter Cases'!$F11="Punjab",'All Cases - Enter Cases'!A11,"") -> 10 | B11: =IF($A11<>"",'All Cases - Enter Cases'!B11,"") -> Faisal Shoes Manufacturing | C11: =IF($A11<>"",'All Cases - Enter Cases'!C11,"") -> Factory | D11: =IF($A11<>"",'All Cases - Enter Cases'!D11,"") -> Plot No.C-62 Taksali Androne Lahore | E11: =IF($A11<>"",'All Cases - Enter Cases'!E11,"") -> Lahore | F11: =IF($A11<>"",'All Cases - Enter Cases'!F11,"") -> Punjab | G11: =IF($A11<>"",'All Cases - Enter Cases'!G11,"") -> SafeMark | H11: =IF($A11<>"",'All Cases - Enter Cases'!H11,"") -> Hugo Boss | I11: =IF($A11<>"",'All Cases - Enter Cases'!I11,"") -> Shoes | ... M11: =IF($A11<>"",'All Cases - Enter Cases'!M11,"") -> 0
A12: =IF('All Cases - Enter Cases'!$F12="Punjab",'All Cases - Enter Cases'!A12,"") -> 11 | B12: =IF($A12<>"",'All Cases - Enter Cases'!B12,"") -> A.K Jeans | C12: =IF($A12<>"",'All Cases - Enter Cases'!C12,"") -> WholeSale | D12: =IF($A12<>"",'All Cases - Enter Cases'!D12,"") -> Shop No.79, Al karim Market , New Anarkali ,Lahore | E12: =IF($A12<>"",'All Cases - Enter Cases'!E12,"") -> Lahore | F12: =IF($A12<>"",'All Cases - Enter Cases'!F12,"") -> Punjab | G12: =IF($A12<>"",'All Cases - Enter Cases'!G12,"") -> SafeMark | H12: =IF($A12<>"",'All Cases - Enter Cases'!H12,"") -> Tommy Hilfiger | I12: =IF($A12<>"",'All Cases - Enter Cases'!I12,"") -> Jeans | ... M12: =IF($A12<>"",'All Cases - Enter Cases'!M12,"") -> 0
A13: =IF('All Cases - Enter Cases'!$F13="Punjab",'All Cases - Enter Cases'!A13,"") -> 12 | B13: =IF($A13<>"",'All Cases - Enter Cases'!B13,"") -> A.K Jeans | C13: =IF($A13<>"",'All Cases - Enter Cases'!C13,"") -> WholeSale | D13: =IF($A13<>"",'All Cases - Enter Cases'!D13,"") -> Shop No.79, Al karim Market , New Anarkali ,Lahore | E13: =IF($A13<>"",'All Cases - Enter Cases'!E13,"") -> Lahore | F13: =IF($A13<>"",'All Cases - Enter Cases'!F13,"") -> Punjab | G13: =IF($A13<>"",'All Cases - Enter Cases'!G13,"") -> SafeMark | H13: =IF($A13<>"",'All Cases - Enter Cases'!H13,"") -> Levis | I13: =IF($A13<>"",'All Cases - Enter Cases'!I13,"") -> Jeans | ... M13: =IF($A13<>"",'All Cases - Enter Cases'!M13,"") -> 0
... A1000: =IF('All Cases - Enter Cases'!$F1000="Punjab",'All Cases - Enter Cases'!A1000,"") | B1000: =IF($A1000<>"",'All Cases - Enter Cases'!B1000,"") | C1000: =IF($A1000<>"",'All Cases - Enter Cases'!C1000,"") | D1000: =IF($A1000<>"",'All Cases - Enter Cases'!D1000,"") | E1000: =IF($A1000<>"",'All Cases - Enter Cases'!E1000,"") | F1000: =IF($A1000<>"",'All Cases - Enter Cases'!F1000,"") | G1000: =IF($A1000<>"",'All Cases - Enter Cases'!G1000,"") | H1000: =IF($A1000<>"",'All Cases - Enter Cases'!H1000,"") | I1000: =IF($A1000<>"",'All Cases - Enter Cases'!I1000,"") | ... M1000: =IF($A1000<>"",'All Cases - Enter Cases'!M1000,"")

Sheet KPK
A1: S.No | B1: Target Name | C1: Target Category | D1: Target Address | E1: City | F1: Provence | G1: Client | H1: Brand Name | I1: Product Name | J1: Case Submission Date | K1: Case Status | L1: Status Date | M1: Remarks
A2: =IF('All Cases - Enter Cases'!$F2="KPK",'All Cases - Enter Cases'!A2,"") | B2: =IF($A2<>"",'All Cases - Enter Cases'!B2,"") | C2: =IF($A2<>"",'All Cases - Enter Cases'!C2,"") | D2: =IF($A2<>"",'All Cases - Enter Cases'!D2,"") | E2: =IF($A2<>"",'All Cases - Enter Cases'!E2,"") | F2: =IF($A2<>"",'All Cases - Enter Cases'!F2,"") | G2: =IF($A2<>"",'All Cases - Enter Cases'!G2,"") | H2: =IF($A2<>"",'All Cases - Enter Cases'!H2,"") | I2: =IF($A2<>"",'All Cases - Enter Cases'!I2,"") | ... M2: =IF($A2<>"",'All Cases - Enter Cases'!M2,"")
A3: =IF('All Cases - Enter Cases'!$F3="KPK",'All Cases - Enter Cases'!A3,"") | B3: =IF($A3<>"",'All Cases - Enter Cases'!B3,"") | C3: =IF($A3<>"",'All Cases - Enter Cases'!C3,"") | D3: =IF($A3<>"",'All Cases - Enter Cases'!D3,"") | E3: =IF($A3<>"",'All Cases - Enter Cases'!E3,"") | F3: =IF($A3<>"",'All Cases - Enter Cases'!F3,"") | G3: =IF($A3<>"",'All Cases - Enter Cases'!G3,"") | H3: =IF($A3<>"",'All Cases - Enter Cases'!H3,"") | I3: =IF($A3<>"",'All Cases - Enter Cases'!I3,"") | ... M3: =IF($A3<>"",'All Cases - Enter Cases'!M3,"")
A4: =IF('All Cases - Enter Cases'!$F4="KPK",'All Cases - Enter Cases'!A4,"") | B4: =IF($A4<>"",'All Cases - Enter Cases'!B4,"") | C4: =IF($A4<>"",'All Cases - Enter Cases'!C4,"") | D4: =IF($A4<>"",'All Cases - Enter Cases'!D4,"") | E4: =IF($A4<>"",'All Cases - Enter Cases'!E4,"") | F4: =IF($A4<>"",'All Cases - Enter Cases'!F4,"") | G4: =IF($A4<>"",'All Cases - Enter Cases'!G4,"") | H4: =IF($A4<>"",'All Cases - Enter Cases'!H4,"") | I4: =IF($A4<>"",'All Cases - Enter Cases'!I4,"") | ... M4: =IF($A4<>"",'All Cases - Enter Cases'!M4,"")
A5: =IF('All Cases - Enter Cases'!$F5="KPK",'All Cases - Enter Cases'!A5,"") | B5: =IF($A5<>"",'All Cases - Enter Cases'!B5,"") | C5: =IF($A5<>"",'All Cases - Enter Cases'!C5,"") | D5: =IF($A5<>"",'All Cases - Enter Cases'!D5,"") | E5: =IF($A5<>"",'All Cases - Enter Cases'!E5,"") | F5: =IF($A5<>"",'All Cases - Enter Cases'!F5,"") | G5: =IF($A5<>"",'All Cases - Enter Cases'!G5,"") | H5: =IF($A5<>"",'All Cases - Enter Cases'!H5,"") | I5: =IF($A5<>"",'All Cases - Enter Cases'!I5,"") | ... M5: =IF($A5<>"",'All Cases - Enter Cases'!M5,"")
A6: =IF('All Cases - Enter Cases'!$F6="KPK",'All Cases - Enter Cases'!A6,"") | B6: =IF($A6<>"",'All Cases - Enter Cases'!B6,"") | C6: =IF($A6<>"",'All Cases - Enter Cases'!C6,"") | D6: =IF($A6<>"",'All Cases - Enter Cases'!D6,"") | E6: =IF($A6<>"",'All Cases - Enter Cases'!E6,"") | F6: =IF($A6<>"",'All Cases - Enter Cases'!F6,"") | G6: =IF($A6<>"",'All Cases - Enter Cases'!G6,"") | H6: =IF($A6<>"",'All Cases - Enter Cases'!H6,"") | I6: =IF($A6<>"",'All Cases - Enter Cases'!I6,"") | ... M6: =IF($A6<>"",'All Cases - Enter Cases'!M6,"")
A7: =IF('All Cases - Enter Cases'!$F7="KPK",'All Cases - Enter Cases'!A7,"") | B7: =IF($A7<>"",'All Cases - Enter Cases'!B7,"") | C7: =IF($A7<>"",'All Cases - Enter Cases'!C7,"") | D7: =IF($A7<>"",'All Cases - Enter Cases'!D7,"") | E7: =IF($A7<>"",'All Cases - Enter Cases'!E7,"") | F7: =IF($A7<>"",'All Cases - Enter Cases'!F7,"") | G7: =IF($A7<>"",'All Cases - Enter Cases'!G7,"") | H7: =IF($A7<>"",'All Cases - Enter Cases'!H7,"") | I7: =IF($A7<>"",'All Cases - Enter Cases'!I7,"") | ... M7: =IF($A7<>"",'All Cases - Enter Cases'!M7,"")
A8: =IF('All Cases - Enter Cases'!$F8="KPK",'All Cases - Enter Cases'!A8,"") | B8: =IF($A8<>"",'All Cases - Enter Cases'!B8,"") | C8: =IF($A8<>"",'All Cases - Enter Cases'!C8,"") | D8: =IF($A8<>"",'All Cases - Enter Cases'!D8,"") | E8: =IF($A8<>"",'All Cases - Enter Cases'!E8,"") | F8: =IF($A8<>"",'All Cases - Enter Cases'!F8,"") | G8: =IF($A8<>"",'All Cases - Enter Cases'!G8,"") | H8: =IF($A8<>"",'All Cases - Enter Cases'!H8,"") | I8: =IF($A8<>"",'All Cases - Enter Cases'!I8,"") | ... M8: =IF($A8<>"",'All Cases - Enter Cases'!M8,"")
A9: =IF('All Cases - Enter Cases'!$F9="KPK",'All Cases - Enter Cases'!A9,"") | B9: =IF($A9<>"",'All Cases - Enter Cases'!B9,"") | C9: =IF($A9<>"",'All Cases - Enter Cases'!C9,"") | D9: =IF($A9<>"",'All Cases - Enter Cases'!D9,"") | E9: =IF($A9<>"",'All Cases - Enter Cases'!E9,"") | F9: =IF($A9<>"",'All Cases - Enter Cases'!F9,"") | G9: =IF($A9<>"",'All Cases - Enter Cases'!G9,"") | H9: =IF($A9<>"",'All Cases - Enter Cases'!H9,"") | I9: =IF($A9<>"",'All Cases - Enter Cases'!I9,"") | ... M9: =IF($A9<>"",'All Cases - Enter Cases'!M9,"")
A10: =IF('All Cases - Enter Cases'!$F10="KPK",'All Cases - Enter Cases'!A10,"") | B10: =IF($A10<>"",'All Cases - Enter Cases'!B10,"") | C10: =IF($A10<>"",'All Cases - Enter Cases'!C10,"") | D10: =IF($A10<>"",'All Cases - Enter Cases'!D10,"") | E10: =IF($A10<>"",'All Cases - Enter Cases'!E10,"") | F10: =IF($A10<>"",'All Cases - Enter Cases'!F10,"") | G10: =IF($A10<>"",'All Cases - Enter Cases'!G10,"") | H10: =IF($A10<>"",'All Cases - Enter Cases'!H10,"") | I10: =IF($A10<>"",'All Cases - Enter Cases'!I10,"") | ... M10: =IF($A10<>"",'All Cases - Enter Cases'!M10,"")
A11: =IF('All Cases - Enter Cases'!$F11="KPK",'All Cases - Enter Cases'!A11,"") | B11: =IF($A11<>"",'All Cases - Enter Cases'!B11,"") | C11: =IF($A11<>"",'All Cases - Enter Cases'!C11,"") | D11: =IF($A11<>"",'All Cases - Enter Cases'!D11,"") | E11: =IF($A11<>"",'All Cases - Enter Cases'!E11,"") | F11: =IF($A11<>"",'All Cases - Enter Cases'!F11,"") | G11: =IF($A11<>"",'All Cases - Enter Cases'!G11,"") | H11: =IF($A11<>"",'All Cases - Enter Cases'!H11,"") | I11: =IF($A11<>"",'All Cases - Enter Cases'!I11,"") | ... M11: =IF($A11<>"",'All Cases - Enter Cases'!M11,"")
A12: =IF('All Cases - Enter Cases'!$F12="KPK",'All Cases - Enter Cases'!A12,"") | B12: =IF($A12<>"",'All Cases - Enter Cases'!B12,"") | C12: =IF($A12<>"",'All Cases - Enter Cases'!C12,"") | D12: =IF($A12<>"",'All Cases - Enter Cases'!D12,"") | E12: =IF($A12<>"",'All Cases - Enter Cases'!E12,"") | F12: =IF($A12<>"",'All Cases - Enter Cases'!F12,"") | G12: =IF($A12<>"",'All Cases - Enter Cases'!G12,"") | H12: =IF($A12<>"",'All Cases - Enter Cases'!H12,"") | I12: =IF($A12<>"",'All Cases - Enter Cases'!I12,"") | ... M12: =IF($A12<>"",'All Cases - Enter Cases'!M12,"")
A13: =IF('All Cases - Enter Cases'!$F13="KPK",'All Cases - Enter Cases'!A13,"") | B13: =IF($A13<>"",'All Cases - Enter Cases'!B13,"") | C13: =IF($A13<>"",'All Cases - Enter Cases'!C13,"") | D13: =IF($A13<>"",'All Cases - Enter Cases'!D13,"") | E13: =IF($A13<>"",'All Cases - Enter Cases'!E13,"") | F13: =IF($A13<>"",'All Cases - Enter Cases'!F13,"") | G13: =IF($A13<>"",'All Cases - Enter Cases'!G13,"") | H13: =IF($A13<>"",'All Cases - Enter Cases'!H13,"") | I13: =IF($A13<>"",'All Cases - Enter Cases'!I13,"") | ... M13: =IF($A13<>"",'All Cases - Enter Cases'!M13,"")
... A1000: =IF('All Cases - Enter Cases'!$F1000="KPK",'All Cases - Enter Cases'!A1000,"") | B1000: =IF($A1000<>"",'All Cases - Enter Cases'!B1000,"") | C1000: =IF($A1000<>"",'All Cases - Enter Cases'!C1000,"") | D1000: =IF($A1000<>"",'All Cases - Enter Cases'!D1000,"") | E1000: =IF($A1000<>"",'All Cases - Enter Cases'!E1000,"") | F1000: =IF($A1000<>"",'All Cases - Enter Cases'!F1000,"") | G1000: =IF($A1000<>"",'All Cases - Enter Cases'!G1000,"") | H1000: =IF($A1000<>"",'All Cases - Enter Cases'!H1000,"") | I1000: =IF($A1000<>"",'All Cases - Enter Cases'!I1000,"") | ... M1000: =IF($A1000<>"",'All Cases - Enter Cases'!M1000,"")

Sheet Balochistan
A1: S.No | B1: Target Name | C1: Target Category | D1: Target Address | E1: City | F1: Provence | G1: Client | H1: Brand Name | I1: Product Name | J1: Case Submission Date | K1: Case Status | L1: Status Date | M1: Remarks
A2: =IF('All Cases - Enter Cases'!$F2="Balochistan",'All Cases - Enter Cases'!A2,"") | B2: =IF($A2<>"",'All Cases - Enter Cases'!B2,"") | C2: =IF($A2<>"",'All Cases - Enter Cases'!C2,"") | D2: =IF($A2<>"",'All Cases - Enter Cases'!D2,"") | E2: =IF($A2<>"",'All Cases - Enter Cases'!E2,"") | F2: =IF($A2<>"",'All Cases - Enter Cases'!F2,"") | G2: =IF($A2<>"",'All Cases - Enter Cases'!G2,"") | H2: =IF($A2<>"",'All Cases - Enter Cases'!H2,"") | I2: =IF($A2<>"",'All Cases - Enter Cases'!I2,"") | ... M2: =IF($A2<>"",'All Cases - Enter Cases'!M2,"")
A3: =IF('All Cases - Enter Cases'!$F3="Balochistan",'All Cases - Enter Cases'!A3,"") | B3: =IF($A3<>"",'All Cases - Enter Cases'!B3,"") | C3: =IF($A3<>"",'All Cases - Enter Cases'!C3,"") | D3: =IF($A3<>"",'All Cases - Enter Cases'!D3,"") | E3: =IF($A3<>"",'All Cases - Enter Cases'!E3,"") | F3: =IF($A3<>"",'All Cases - Enter Cases'!F3,"") | G3: =IF($A3<>"",'All Cases - Enter Cases'!G3,"") | H3: =IF($A3<>"",'All Cases - Enter Cases'!H3,"") | I3: =IF($A3<>"",'All Cases - Enter Cases'!I3,"") | ... M3: =IF($A3<>"",'All Cases - Enter Cases'!M3,"")
A4: =IF('All Cases - Enter Cases'!$F4="Balochistan",'All Cases - Enter Cases'!A4,"") | B4: =IF($A4<>"",'All Cases - Enter Cases'!B4,"") | C4: =IF($A4<>"",'All Cases - Enter Cases'!C4,"") | D4: =IF($A4<>"",'All Cases - Enter Cases'!D4,"") | E4: =IF($A4<>"",'All Cases - Enter Cases'!E4,"") | F4: =IF($A4<>"",'All Cases - Enter Cases'!F4,"") | G4: =IF($A4<>"",'All Cases - Enter Cases'!G4,"") | H4: =IF($A4<>"",'All Cases - Enter Cases'!H4,"") | I4: =IF($A4<>"",'All Cases - Enter Cases'!I4,"") | ... M4: =IF($A4<>"",'All Cases - Enter Cases'!M4,"")
A5: =IF('All Cases - Enter Cases'!$F5="Balochistan",'All Cases - Enter Cases'!A5,"") | B5: =IF($A5<>"",'All Cases - Enter Cases'!B5,"") | C5: =IF($A5<>"",'All Cases - Enter Cases'!C5,"") | D5: =IF($A5<>"",'All Cases - Enter Cases'!D5,"") | E5: =IF($A5<>"",'All Cases - Enter Cases'!E5,"") | F5: =IF($A5<>"",'All Cases - Enter Cases'!F5,"") | G5: =IF($A5<>"",'All Cases - Enter Cases'!G5,"") | H5: =IF($A5<>"",'All Cases - Enter Cases'!H5,"") | I5: =IF($A5<>"",'All Cases - Enter Cases'!I5,"") | ... M5: =IF($A5<>"",'All Cases - Enter Cases'!M5,"")
A6: =IF('All Cases - Enter Cases'!$F6="Balochistan",'All Cases - Enter Cases'!A6,"") | B6: =IF($A6<>"",'All Cases - Enter Cases'!B6,"") | C6: =IF($A6<>"",'All Cases - Enter Cases'!C6,"") | D6: =IF($A6<>"",'All Cases - Enter Cases'!D6,"") | E6: =IF($A6<>"",'All Cases - Enter Cases'!E6,"") | F6: =IF($A6<>"",'All Cases - Enter Cases'!F6,"") | G6: =IF($A6<>"",'All Cases - Enter Cases'!G6,"") | H6: =IF($A6<>"",'All Cases - Enter Cases'!H6,"") | I6: =IF($A6<>"",'All Cases - Enter Cases'!I6,"") | ... M6: =IF($A6<>"",'All Cases - Enter Cases'!M6,"")
A7: =IF('All Cases - Enter Cases'!$F7="Balochistan",'All Cases - Enter Cases'!A7,"") | B7: =IF($A7<>"",'All Cases - Enter Cases'!B7,"") | C7: =IF($A7<>"",'All Cases - Enter Cases'!C7,"") | D7: =IF($A7<>"",'All Cases - Enter Cases'!D7,"") | E7: =IF($A7<>"",'All Cases - Enter Cases'!E7,"") | F7: =IF($A7<>"",'All Cases - Enter Cases'!F7,"") | G7: =IF($A7<>"",'All Cases - Enter Cases'!G7,"") | H7: =IF($A7<>"",'All Cases - Enter Cases'!H7,"") | I7: =IF($A7<>"",'All Cases - Enter Cases'!I7,"") | ... M7: =IF($A7<>"",'All Cases - Enter Cases'!M7,"")
A8: =IF('All Cases - Enter Cases'!$F8="Balochistan",'All Cases - Enter Cases'!A8,"") | B8: =IF($A8<>"",'All Cases - Enter Cases'!B8,"") | C8: =IF($A8<>"",'All Cases - Enter Cases'!C8,"") | D8: =IF($A8<>"",'All Cases - Enter Cases'!D8,"") | E8: =IF($A8<>"",'All Cases - Enter Cases'!E8,"") | F8: =IF($A8<>"",'All Cases - Enter Cases'!F8,"") | G8: =IF($A8<>"",'All Cases - Enter Cases'!G8,"") | H8: =IF($A8<>"",'All Cases - Enter Cases'!H8,"") | I8: =IF($A8<>"",'All Cases - Enter Cases'!I8,"") | ... M8: =IF($A8<>"",'All Cases - Enter Cases'!M8,"")
A9: =IF('All Cases - Enter Cases'!$F9="Balochistan",'All Cases - Enter Cases'!A9,"") | B9: =IF($A9<>"",'All Cases - Enter Cases'!B9,"") | C9: =IF($A9<>"",'All Cases - Enter Cases'!C9,"") | D9: =IF($A9<>"",'All Cases - Enter Cases'!D9,"") | E9: =IF($A9<>"",'All Cases - Enter Cases'!E9,"") | F9: =IF($A9<>"",'All Cases - Enter Cases'!F9,"") | G9: =IF($A9<>"",'All Cases - Enter Cases'!G9,"") | H9: =IF($A9<>"",'All Cases - Enter Cases'!H9,"") | I9: =IF($A9<>"",'All Cases - Enter Cases'!I9,"") | ... M9: =IF($A9<>"",'All Cases - Enter Cases'!M9,"")
A10: =IF('All Cases - Enter Cases'!$F10="Balochistan",'All Cases - Enter Cases'!A10,"") | B10: =IF($A10<>"",'All Cases - Enter Cases'!B10,"") | C10: =IF($A10<>"",'All Cases - Enter Cases'!C10,"") | D10: =IF($A10<>"",'All Cases - Enter Cases'!D10,"") | E10: =IF($A10<>"",'All Cases - Enter Cases'!E10,"") | F10: =IF($A10<>"",'All Cases - Enter Cases'!F10,"") | G10: =IF($A10<>"",'All Cases - Enter Cases'!G10,"") | H10: =IF($A10<>"",'All Cases - Enter Cases'!H10,"") | I10: =IF($A10<>"",'All Cases - Enter Cases'!I10,"") | ... M10: =IF($A10<>"",'All Cases - Enter Cases'!M10,"")
A11: =IF('All Cases - Enter Cases'!$F11="Balochistan",'All Cases - Enter Cases'!A11,"") | B11: =IF($A11<>"",'All Cases - Enter Cases'!B11,"") | C11: =IF($A11<>"",'All Cases - Enter Cases'!C11,"") | D11: =IF($A11<>"",'All Cases - Enter Cases'!D11,"") | E11: =IF($A11<>"",'All Cases - Enter Cases'!E11,"") | F11: =IF($A11<>"",'All Cases - Enter Cases'!F11,"") | G11: =IF($A11<>"",'All Cases - Enter Cases'!G11,"") | H11: =IF($A11<>"",'All Cases - Enter Cases'!H11,"") | I11: =IF($A11<>"",'All Cases - Enter Cases'!I11,"") | ... M11: =IF($A11<>"",'All Cases - Enter Cases'!M11,"")
A12: =IF('All Cases - Enter Cases'!$F12="Balochistan",'All Cases - Enter Cases'!A12,"") | B12: =IF($A12<>"",'All Cases - Enter Cases'!B12,"") | C12: =IF($A12<>"",'All Cases - Enter Cases'!C12,"") | D12: =IF($A12<>"",'All Cases - Enter Cases'!D12,"") | E12: =IF($A12<>"",'All Cases - Enter Cases'!E12,"") | F12: =IF($A12<>"",'All Cases - Enter Cases'!F12,"") | G12: =IF($A12<>"",'All Cases - Enter Cases'!G12,"") | H12: =IF($A12<>"",'All Cases - Enter Cases'!H12,"") | I12: =IF($A12<>"",'All Cases - Enter Cases'!I12,"") | ... M12: =IF($A12<>"",'All Cases - Enter Cases'!M12,"")
A13: =IF('All Cases - Enter Cases'!$F13="Balochistan",'All Cases - Enter Cases'!A13,"") | B13: =IF($A13<>"",'All Cases - Enter Cases'!B13,"") | C13: =IF($A13<>"",'All Cases - Enter Cases'!C13,"") | D13: =IF($A13<>"",'All Cases - Enter Cases'!D13,"") | E13: =IF($A13<>"",'All Cases - Enter Cases'!E13,"") | F13: =IF($A13<>"",'All Cases - Enter Cases'!F13,"") | G13: =IF($A13<>"",'All Cases - Enter Cases'!G13,"") | H13: =IF($A13<>"",'All Cases - Enter Cases'!H13,"") | I13: =IF($A13<>"",'All Cases - Enter Cases'!I13,"") | ... M13: =IF($A13<>"",'All Cases - Enter Cases'!M13,"")
... A1000: =IF('All Cases - Enter Cases'!$F1000="Balochistan",'All Cases - Enter Cases'!A1000,"") | B1000: =IF($A1000<>"",'All Cases - Enter Cases'!B1000,"") | C1000: =IF($A1000<>"",'All Cases - Enter Cases'!C1000,"") | D1000: =IF($A1000<>"",'All Cases - Enter Cases'!D1000,"") | E1000: =IF($A1000<>"",'All Cases - Enter Cases'!E1000,"") | F1000: =IF($A1000<>"",'All Cases - Enter Cases'!F1000,"") | G1000: =IF($A1000<>"",'All Cases - Enter Cases'!G1000,"") | H1000: =IF($A1000<>"",'All Cases - Enter Cases'!H1000,"") | I1000: =IF($A1000<>"",'All Cases - Enter Cases'!I1000,"") | ... M1000: =IF($A1000<>"",'All Cases - Enter Cases'!M1000,"")

Sheet Approved-In-Depth
A1: S.No | B1: Due Date | C1: Target Name | D1: Target Category | E1: Target Address | F1: City | G1: Provence | H1: Client | I1: Brand Name | J1: Product Name | K1: Case Submission Date | L1: Case Approved Date | M1: Remarks | N1: Due Date Override
A2: =IF('All Cases - Enter Cases'!$K2="Approved",'All Cases - Enter Cases'!A2,"") -> 1 | B2: =IF($N2<>"",$N2,IF($A2<>"",'All Cases - Enter Cases'!$L2+7,"")) -> 46010 | C2: =IF($A2<>"",'All Cases - Enter Cases'!B2,"") -> Marfani Traders | D2: =IF($A2<>"",'All Cases - Enter Cases'!C2,"") -> Shop | E2: =IF($A2<>"",'All Cases - Enter Cases'!D2,"") -> Godown No. S-19 West Warf, New Lipton Gali ,Karachi | F2: =IF($A2<>"",'All Cases - Enter Cases'!E2,"") -> Karachi | G2: =IF($A2<>"",'All Cases - Enter Cases'!F2,"") -> Sindh | H2: =IF($A2<>"",'All Cases - Enter Cases'!G2,"") -> OneWorld | I2: =IF($A2<>"",'All Cases - Enter Cases'!H2,"") -> Wd-40 | J2: =IF($A2<>"",'All Cases - Enter Cases'!I2,"") -> Fluid | ... M2: =IF($A2<>"",'All Cases - Enter Cases'!L2,"") -> 46003
A3: =IF('All Cases - Enter Cases'!$K3="Approved",'All Cases - Enter Cases'!A3,"") -> 2 | B3: =IF($N3<>"",$N3,IF($A3<>"",'All Cases - Enter Cases'!$L3+7,"")) -> 46042 | C3: =IF($A3<>"",'All Cases - Enter Cases'!B3,"") -> Sami Garments Factory | D3: =IF($A3<>"",'All Cases - Enter Cases'!C3,"") -> Factory | E3: =IF($A3<>"",'All Cases - Enter Cases'!D3,"") -> Plot No.L-27 Sector 12B Industrial Area ,New Karachi | F3: =IF($A3<>"",'All Cases - Enter Cases'!E3,"") -> Karachi | G3: =IF($A3<>"",'All Cases - Enter Cases'!F3,"") -> Sindh | H3: =IF($A3<>"",'All Cases - Enter Cases'!G3,"") -> SafeMark | I3: =IF($A3<>"",'All Cases - Enter Cases'!H3,"") -> Reebok | J3: =IF($A3<>"",'All Cases - Enter Cases'!I3,"") -> Garments | ... M3: =IF($A3<>"",'All Cases - Enter Cases'!L3,"") -> 46035
A4: =IF('All Cases - Enter Cases'!$K4="Approved",'All Cases - Enter Cases'!A4,"") -> 3 | B4: =IF($N4<>"",$N4,IF($A4<>"",'All Cases - Enter Cases'!$L4+7,"")) -> 46042 | C4: =IF($A4<>"",'All Cases - Enter Cases'!B4,"") -> Sami Garments Factory | D4: =IF($A4<>"",'All Cases - Enter Cases'!C4,"") -> Factory | E4: =IF($A4<>"",'All Cases - Enter Cases'!D4,"") -> Plot No.L-27 Sector 12B Industrial Area ,New Karachi | F4: =IF($A4<>"",'All Cases - Enter Cases'!E4,"") -> Karachi | G4: =IF($A4<>"",'All Cases - Enter Cases'!F4,"") -> Sindh | H4: =IF($A4<>"",'All Cases - Enter Cases'!G4,"") -> SafeMark | I4: =IF($A4<>"",'All Cases - Enter Cases'!H4,"") -> Champion | J4: =IF($A4<>"",'All Cases - Enter Cases'!I4,"") -> Garments | ... M4: =IF($A4<>"",'All Cases - Enter Cases'!L4,"") -> 46035
A5: =IF('All Cases - Enter Cases'!$K5="Approved",'All Cases - Enter Cases'!A5,"") -> 4 | B5: =IF($N5<>"",$N5,IF($A5<>"",'All Cases - Enter Cases'!$L5+7,"")) -> 46042 | C5: =IF($A5<>"",'All Cases - Enter Cases'!B5,"") -> Sami Garments Factory | D5: =IF($A5<>"",'All Cases - Enter Cases'!C5,"") -> Factory | E5: =IF($A5<>"",'All Cases - Enter Cases'!D5,"") -> Plot No.L-27 Sector 12B Industrial Area ,New Karachi | F5: =IF($A5<>"",'All Cases - Enter Cases'!E5,"") -> Karachi | G5: =IF($A5<>"",'All Cases - Enter Cases'!F5,"") -> Sindh | H5: =IF($A5<>"",'All Cases - Enter Cases'!G5,"") -> SafeMark | I5: =IF($A5<>"",'All Cases - Enter Cases'!H5,"") -> Hugo Boss | J5: =IF($A5<>"",'All Cases - Enter Cases'!I5,"") -> Garments | ... M5: =IF($A5<>"",'All Cases - Enter Cases'!L5,"") -> 46035
A6: =IF('All Cases - Enter Cases'!$K6="Approved",'All Cases - Enter Cases'!A6,"") -> 5 | B6: =IF($N6<>"",$N6,IF($A6<>"",'All Cases - Enter Cases'!$L6+7,"")) -> 46046 | C6: =IF($A6<>"",'All Cases - Enter Cases'!B6,"") -> Faisal Shoes Manufacturing | D6: =IF($A6<>"",'All Cases - Enter Cases'!C6,"") -> Factory | E6: =IF($A6<>"",'All Cases - Enter Cases'!D6,"") -> Plot No.C-62 Taksali Androne Lahore | F6: =IF($A6<>"",'All Cases - Enter Cases'!E6,"") -> Lahore | G6: =IF($A6<>"",'All Cases - Enter Cases'!F6,"") -> Punjab | H6: =IF($A6<>"",'All Cases - Enter Cases'!G6,"") -> SafeMark | I6: =IF($A6<>"",'All Cases - Enter Cases'!H6,"") -> Tommy Hilfiger | J6: =IF($A6<>"",'All Cases - Enter Cases'!I6,"") -> Shoes | ... M6: =IF($A6<>"",'All Cases - Enter Cases'!L6,"") -> 46039
A7: =IF('All Cases - Enter Cases'!$K7="Approved",'All Cases - Enter Cases'!A7,"") -> 6 | B7: =IF($N7<>"",$N7,IF($A7<>"",'All Cases - Enter Cases'!$L7+7,"")) -> 46047 | C7: =IF($A7<>"",'All Cases - Enter Cases'!B7,"") -> Faisal Shoes Manufacturing | D7: =IF($A7<>"",'All Cases - Enter Cases'!C7,"") -> Factory | E7: =IF($A7<>"",'All Cases - Enter Cases'!D7,"") -> Plot No.C-62 Taksali Androne Lahore | F7: =IF($A7<>"",'All Cases - Enter Cases'!E7,"") -> Lahore | G7: =IF($A7<>"",'All Cases - Enter Cases'!F7,"") -> Punjab | H7: =IF($A7<>"",'All Cases - Enter Cases'!G7,"") -> SafeMark | I7: =IF($A7<>"",'All Cases - Enter Cases'!H7,"") -> Calvin Klein | J7: =IF($A7<>"",'All Cases - Enter Cases'!I7,"") -> Shoes | ... M7: =IF($A7<>"",'All Cases - Enter Cases'!L7,"") -> 46040
A8: =IF('All Cases - Enter Cases'!$K8="Approved",'All Cases - Enter Cases'!A8,"") -> 7 | B8: =IF($N8<>"",$N8,IF($A8<>"",'All Cases - Enter Cases'!$L8+7,"")) -> 46036 | C8: =IF($A8<>"",'All Cases - Enter Cases'!B8,"") -> Faisal Shoes Manufacturing | D8: =IF($A8<>"",'All Cases - Enter Cases'!C8,"") -> Factory | E8: =IF($A8<>"",'All Cases - Enter Cases'!D8,"") -> Plot No.C-62 Taksali Androne Lahore | F8: =IF($A8<>"",'All Cases - Enter Cases'!E8,"") -> Lahore | G8: =IF($A8<>"",'All Cases - Enter Cases'!F8,"") -> Punjab | H8: =IF($A8<>"",'All Cases - Enter Cases'!G8,"") -> SafeMark | I8: =IF($A8<>"",'All Cases - Enter Cases'!H8,"") -> Reebok | J8: =IF($A8<>"",'All Cases - Enter Cases'!I8,"") -> Shoes | ... M8: =IF($A8<>"",'All Cases - Enter Cases'!L8,"") -> 46029
A9: =IF('All Cases - Enter Cases'!$K9="Approved",'All Cases - Enter Cases'!A9,"") -> 8 | B9: =IF($N9<>"",$N9,IF($A9<>"",'All Cases - Enter Cases'!$L9+7,"")) -> 46048 | C9: =IF($A9<>"",'All Cases - Enter Cases'!B9,"") -> Faisal Shoes Manufacturing | D9: =IF($A9<>"",'All Cases - Enter Cases'!C9,"") -> Factory | E9: =IF($A9<>"",'All Cases - Enter Cases'!D9,"") -> Plot No.C-62 Taksali Androne Lahore | F9: =IF($A9<>"",'All Cases - Enter Cases'!E9,"") -> Lahore | G9: =IF($A9<>"",'All Cases - Enter Cases'!F9,"") -> Punjab | H9: =IF($A9<>"",'All Cases - Enter Cases'!G9,"") -> AA | I9: =IF($A9<>"",'All Cases - Enter Cases'!H9,"") -> Gucci | J9: =IF($A9<>"",'All Cases - Enter Cases'!I9,"") -> Shoes | ... M9: =IF($A9<>"",'All Cases - Enter Cases'!L9,"") -> 46041
A10: =IF('All Cases - Enter Cases'!$K10="Approved",'All Cases - Enter Cases'!A10,"") -> 9 | B10: =IF($N10<>"",$N10,IF($A10<>"",'All Cases - Enter Cases'!$L10+7,"")) -> 46036 | C10: =IF($A10<>"",'All Cases - Enter Cases'!B10,"") -> Faisal Shoes Manufacturing | D10: =IF($A10<>"",'All Cases - Enter Cases'!C10,"") -> Factory | E10: =IF($A10<>"",'All Cases - Enter Cases'!D10,"") -> Plot No.C-62 Taksali Androne Lahore | F10: =IF($A10<>"",'All Cases - Enter Cases'!E10,"") -> Lahore | G10: =IF($A10<>"",'All Cases - Enter Cases'!F10,"") -> Punjab | H10: =IF($A10<>"",'All Cases - Enter Cases'!G10,"") -> SafeMark | I10: =IF($A10<>"",'All Cases - Enter Cases'!H10,"") -> New Balance | J10: =IF($A10<>"",'All Cases - Enter Cases'!I10,"") -> Shoes | ... M10: =IF($A10<>"",'All Cases - Enter Cases'!L10,"") -> 46029
A11: =IF('All Cases - Enter Cases'!$K11="Approved",'All Cases - Enter Cases'!A11,"") -> 10 | B11: =IF($N11<>"",$N11,IF($A11<>"",'All Cases - Enter Cases'!$L11+7,"")) -> 46036 | C11: =IF($A11<>"",'All Cases - Enter Cases'!B11,"") -> Faisal Shoes Manufacturing | D11: =IF($A11<>"",'All Cases - Enter Cases'!C11,"") -> Factory | E11: =IF($A11<>"",'All Cases - Enter Cases'!D11,"") -> Plot No.C-62 Taksali Androne Lahore | F11: =IF($A11<>"",'All Cases - Enter Cases'!E11,"") -> Lahore | G11: =IF($A11<>"",'All Cases - Enter Cases'!F11,"") -> Punjab | H11: =IF($A11<>"",'All Cases - Enter Cases'!G11,"") -> SafeMark | I11: =IF($A11<>"",'All Cases - Enter Cases'!H11,"") -> Hugo Boss | J11: =IF($A11<>"",'All Cases - Enter Cases'!I11,"") -> Shoes | ... M11: =IF($A11<>"",'All Cases - Enter Cases'!L11,"") -> 46029
A12: =IF('All Cases - Enter Cases'!$K12="Approved",'All Cases - Enter Cases'!A12,"") -> 11 | B12: =IF($N12<>"",$N12,IF($A12<>"",'All Cases - Enter Cases'!$L12+7,"")) -> 46052 | C12: =IF($A12<>"",'All Cases - Enter Cases'!B12,"") -> A.K Jeans | D12: =IF($A12<>"",'All Cases - Enter Cases'!C12,"") -> WholeSale | E12: =IF($A12<>"",'All Cases - Enter Cases'!D12,"") -> Shop No.79, Al karim Market , New Anarkali ,Lahore | F12: =IF($A12<>"",'All Cases - Enter Cases'!E12,"") -> Lahore | G12: =IF($A12<>"",'All Cases - Enter Cases'!F12,"") -> Punjab | H12: =IF($A12<>"",'All Cases - Enter Cases'!G12,"") -> SafeMark | I12: =IF($A12<>"",'All Cases - Enter Cases'!H12,"") -> Tommy Hilfiger | J12: =IF($A12<>"",'All Cases - Enter Cases'!I12,"") -> Jeans | ... M12: =IF($A12<>"",'All Cases - Enter Cases'!L12,"") -> 46045
A13: =IF('All Cases - Enter Cases'!$K13="Approved",'All Cases - Enter Cases'!A13,"") -> 12 | B13: =IF($N13<>"",$N13,IF($A13<>"",'All Cases - Enter Cases'!$L13+7,"")) -> 46045 | C13: =IF($A13<>"",'All Cases - Enter Cases'!B13,"") -> A.K Jeans | D13: =IF($A13<>"",'All Cases - Enter Cases'!C13,"") -> WholeSale | E13: =IF($A13<>"",'All Cases - Enter Cases'!D13,"") -> Shop No.79, Al karim Market , New Anarkali ,Lahore | F13: =IF($A13<>"",'All Cases - Enter Cases'!E13,"") -> Lahore | G13: =IF($A13<>"",'All Cases - Enter Cases'!F13,"") -> Punjab | H13: =IF($A13<>"",'All Cases - Enter Cases'!G13,"") -> SafeMark | I13: =IF($A13<>"",'All Cases - Enter Cases'!H13,"") -> Levis | J13: =IF($A13<>"",'All Cases - Enter Cases'!I13,"") -> Jeans | ... M13: =IF($A13<>"",'All Cases - Enter Cases'!L13,"") -> 46038
... A1000: =IF('All Cases - Enter Cases'!$K1000="Approved",'All Cases - Enter Cases'!A1000,"") | B1000: =IF($N1000<>"",$N1000,IF($A1000<>"",'All Cases - Enter Cases'!$L1000+7,"")) | C1000: =IF($A1000<>"",'All Cases - Enter Cases'!B1000,"") | D1000: =IF($A1000<>"",'All Cases - Enter Cases'!C1000,"") | E1000: =IF($A1000<>"",'All Cases - Enter Cases'!D1000,"") | F1000: =IF($A1000<>"",'All Cases - Enter Cases'!E1000,"") | G1000: =IF($A1000<>"",'All Cases - Enter Cases'!F1000,"") | H1000: =IF($A1000<>"",'All Cases - Enter Cases'!G1000,"") | I1000: =IF($A1000<>"",'All Cases - Enter Cases'!H1000,"") | J1000: =IF($A1000<>"",'All Cases - Enter Cases'!I1000,"") | ... M1000: =IF($A1000<>"",'All Cases - Enter Cases'!L1000,"")

Sheet Approved-Enforcement
A1: S.No | B1: Due Date | C1: Target Name | D1: Target Category | E1: Target Address | F1: City | G1: Provence | H1: Client | I1: Brand Name | J1: Product Name | K1: Case Submission Date | L1: Case Approved Date | M1: In-Depth Due Date | N1: Remarks | O1: Due Date Override
A2: =IF('Approved-In-Depth'!$A2<>"",'Approved-In-Depth'!A2,"") -> 1 | B2: =IF($O2<>"",$O2,IF($A2<>"",'Approved-In-Depth'!$B2+7,"")) -> 46017 | C2: =IF($A2<>"",'Approved-In-Depth'!C2,"") -> Marfani Traders | D2: =IF($A2<>"",'Approved-In-Depth'!D2,"") -> Shop | E2: =IF($A2<>"",'Approved-In-Depth'!E2,"") -> Godown No. S-19 West Warf, New Lipton Gali ,Karachi | F2: =IF($A2<>"",'Approved-In-Depth'!F2,"") -> Karachi | G2: =IF($A2<>"",'Approved-In-Depth'!G2,"") -> Sindh | H2: =IF($A2<>"",'Approved-In-Depth'!H2,"") -> OneWorld | I2: =IF($A2<>"",'Approved-In-Depth'!I2,"") -> Wd-40 | J2: =IF($A2<>"",'Approved-In-Depth'!J2,"") -> Fluid | ... M2: =IF($A2<>"",'Approved-In-Depth'!M2,"") -> 46003
A3: =IF('Approved-In-Depth'!$A3<>"",'Approved-In-Depth'!A3,"") -> 2 | B3: =IF($O3<>"",$O3,IF($A3<>"",'Approved-In-Depth'!$B3+7,"")) -> 46049 | C3: =IF($A3<>"",'Approved-In-Depth'!C3,"") -> Sami Garments Factory | D3: =IF($A3<>"",'Approved-In-Depth'!D3,"") -> Factory | E3: =IF($A3<>"",'Approved-In-Depth'!E3,"") -> Plot No.L-27 Sector 12B Industrial Area ,New Karachi | F3: =IF($A3<>"",'Approved-In-Depth'!F3,"") -> Karachi | G3: =IF($A3<>"",'Approved-In-Depth'!G3,"") -> Sindh | H3: =IF($A3<>"",'Approved-In-Depth'!H3,"") -> SafeMark | I3: =IF($A3<>"",'Approved-In-Depth'!I3,"") -> Reebok | J3: =IF($A3<>"",'Approved-In-Depth'!J3,"") -> Garments | ... M3: =IF($A3<>"",'Approved-In-Depth'!M3,"") -> 46035
A4: =IF('Approved-In-Depth'!$A4<>"",'Approved-In-Depth'!A4,"") -> 3 | B4: =IF($O4<>"",$O4,IF($A4<>"",'Approved-In-Depth'!$B4+7,"")) -> 46049 | C4: =IF($A4<>"",'Approved-In-Depth'!C4,"") -> Sami Garments Factory | D4: =IF($A4<>"",'Approved-In-Depth'!D4,"") -> Factory | E4: =IF($A4<>"",'Approved-In-Depth'!E4,"") -> Plot No.L-27 Sector 12B Industrial Area ,New Karachi | F4: =IF($A4<>"",'Approved-In-Depth'!F4,"") -> Karachi | G4: =IF($A4<>"",'Approved-In-Depth'!G4,"") -> Sindh | H4: =IF($A4<>"",'Approved-In-Depth'!H4,"") -> SafeMark | I4: =IF($A4<>"",'Approved-In-Depth'!I4,"") -> Champion | J4: =IF($A4<>"",'Approved-In-Depth'!J4,"") -> Garments | ... M4: =IF($A4<>"",'Approved-In-Depth'!M4,"") -> 46035
A5: =IF('Approved-In-Depth'!$A5<>"",'Approved-In-Depth'!A5,"") -> 4 | B5: =IF($O5<>"",$O5,IF($A5<>"",'Approved-In-Depth'!$B5+7,"")) -> 46049 | C5: =IF($A5<>"",'Approved-In-Depth'!C5,"") -> Sami Garments Factory | D5: =IF($A5<>"",'Approved-In-Depth'!D5,"") -> Factory | E5: =IF($A5<>"",'Approved-In-Depth'!E5,"") -> Plot No.L-27 Sector 12B Industrial Area ,New Karachi | F5: =IF($A5<>"",'Approved-In-Depth'!F5,"") -> Karachi | G5: =IF($A5<>"",'Approved-In-Depth'!G5,"") -> Sindh | H5: =IF($A5<>"",'Approved-In-Depth'!H5,"") -> SafeMark | I5: =IF($A5<>"",'Approved-In-Depth'!I5,"") -> Hugo Boss | J5: =IF($A5<>"",'Approved-In-Depth'!J5,"") -> Garments | ... M5: =IF($A5<>"",'Approved-In-Depth'!M5,"") -> 46035
A6: =IF('Approved-In-Depth'!$A6<>"",'Approved-In-Depth'!A6,"") -> 5 | B6: =IF($O6<>"",$O6,IF($A6<>"",'Approved-In-Depth'!$B6+7,"")) -> 46053 | C6: =IF($A6<>"",'Approved-In-Depth'!C6,"") -> Faisal Shoes Manufacturing | D6: =IF($A6<>"",'Approved-In-Depth'!D6,"") -> Factory | E6: =IF($A6<>"",'Approved-In-Depth'!E6,"") -> Plot No.C-62 Taksali Androne Lahore | F6: =IF($A6<>"",'Approved-In-Depth'!F6,"") -> Lahore | G6: =IF($A6<>"",'Approved-In-Depth'!G6,"") -> Punjab | H6: =IF($A6<>"",'Approved-In-Depth'!H6,"") -> SafeMark | I6: =IF($A6<>"",'Approved-In-Depth'!I6,"") -> Tommy Hilfiger | J6: =IF($A6<>"",'Approved-In-Depth'!J6,"") -> Shoes | ... M6: =IF($A6<>"",'Approved-In-Depth'!M6,"") -> 46039
A7: =IF('Approved-In-Depth'!$A7<>"",'Approved-In-Depth'!A7,"") -> 6 | B7: =IF($O7<>"",$O7,IF($A7<>"",'Approved-In-Depth'!$B7+7,"")) -> 46054 | C7: =IF($A7<>"",'Approved-In-Depth'!C7,"") -> Faisal Shoes Manufacturing | D7: =IF($A7<>"",'Approved-In-Depth'!D7,"") -> Factory | E7: =IF($A7<>"",'Approved-In-Depth'!E7,"") -> Plot No.C-62 Taksali Androne Lahore | F7: =IF($A7<>"",'Approved-In-Depth'!F7,"") -> Lahore | G7: =IF($A7<>"",'Approved-In-Depth'!G7,"") -> Punjab | H7: =IF($A7<>"",'Approved-In-Depth'!H7,"") -> SafeMark | I7: =IF($A7<>"",'Approved-In-Depth'!I7,"") -> Calvin Klein | J7: =IF($A7<>"",'Approved-In-Depth'!J7,"") -> Shoes | ... M7: =IF($A7<>"",'Approved-In-Depth'!M7,"") -> 46040
A8: =IF('Approved-In-Depth'!$A8<>"",'Approved-In-Depth'!A8,"") -> 7 | B8: =IF($O8<>"",$O8,IF($A8<>"",'Approved-In-Depth'!$B8+7,"")) -> 46043 | C8: =IF($A8<>"",'Approved-In-Depth'!C8,"") -> Faisal Shoes Manufacturing | D8: =IF($A8<>"",'Approved-In-Depth'!D8,"") -> Factory | E8: =IF($A8<>"",'Approved-In-Depth'!E8,"") -> Plot No.C-62 Taksali Androne Lahore | F8: =IF($A8<>"",'Approved-In-Depth'!F8,"") -> Lahore | G8: =IF($A8<>"",'Approved-In-Depth'!G8,"") -> Punjab | H8: =IF($A8<>"",'Approved-In-Depth'!H8,"") -> SafeMark | I8: =IF($A8<>"",'Approved-In-Depth'!I8,"") -> Reebok | J8: =IF($A8<>"",'Approved-In-Depth'!J8,"") -> Shoes | ... M8: =IF($A8<>"",'Approved-In-Depth'!M8,"") -> 46029
A9: =IF('Approved-In-Depth'!$A9<>"",'Approved-In-Depth'!A9,"") -> 8 | B9: =IF($O9<>"",$O9,IF($A9<>"",'Approved-In-Depth'!$B9+7,"")) -> 46055 | C9: =IF($A9<>"",'Approved-In-Depth'!C9,"") -> Faisal Shoes Manufacturing | D9: =IF($A9<>"",'Approved-In-Depth'!D9,"") -> Factory | E9: =IF($A9<>"",'Approved-In-Depth'!E9,"") -> Plot No.C-62 Taksali Androne Lahore | F9: =IF($A9<>"",'Approved-In-Depth'!F9,"") -> Lahore | G9: =IF($A9<>"",'Approved-In-Depth'!G9,"") -> Punjab | H9: =IF($A9<>"",'Approved-In-Depth'!H9,"") -> AA | I9: =IF($A9<>"",'Approved-In-Depth'!I9,"") -> Gucci | J9: =IF($A9<>"",'Approved-In-Depth'!J9,"") -> Shoes | ... M9: =IF($A9<>"",'Approved-In-Depth'!M9,"") -> 46041
A10: =IF('Approved-In-Depth'!$A10<>"",'Approved-In-Depth'!A10,"") -> 9 | B10: =IF($O10<>"",$O10,IF($A10<>"",'Approved-In-Depth'!$B10+7,"")) -> 46043 | C10: =IF($A10<>"",'Approved-In-Depth'!C10,"") -> Faisal Shoes Manufacturing | D10: =IF($A10<>"",'Approved-In-Depth'!D10,"") -> Factory | E10: =IF($A10<>"",'Approved-In-Depth'!E10,"") -> Plot No.C-62 Taksali Androne Lahore | F10: =IF($A10<>"",'Approved-In-Depth'!F10,"") -> Lahore | G10: =IF($A10<>"",'Approved-In-Depth'!G10,"") -> Punjab | H10: =IF($A10<>"",'Approved-In-Depth'!H10,"") -> SafeMark | I10: =IF($A10<>"",'Approved-In-Depth'!I10,"") -> New Balance | J10: =IF($A10<>"",'Approved-In-Depth'!J10,"") -> Shoes | ... M10: =IF($A10<>"",'Approved-In-Depth'!M10,"") -> 46029
A11: =IF('Approved-In-Depth'!$A11<>"",'Approved-In-Depth'!A11,"") -> 10 | B11: =IF($O11<>"",$O11,IF($A11<>"",'Approved-In-Depth'!$B11+7,"")) -> 46043 | C11: =IF($A11<>"",'Approved-In-Depth'!C11,"") -> Faisal Shoes Manufacturing | D11: =IF($A11<>"",'Approved-In-Depth'!D11,"") -> Factory | E11: =IF($A11<>"",'Approved-In-Depth'!E11,"") -> Plot No.C-62 Taksali Androne Lahore | F11: =IF($A11<>"",'Approved-In-Depth'!F11,"") -> Lahore | G11: =IF($A11<>"",'Approved-In-Depth'!G11,"") -> Punjab | H11: =IF($A11<>"",'Approved-In-Depth'!H11,"") -> SafeMark | I11: =IF($A11<>"",'Approved-In-Depth'!I11,"") -> Hugo Boss | J11: =IF($A11<>"",'Approved-In-Depth'!J11,"") -> Shoes | ... M11: =IF($A11<>"",'Approved-In-Depth'!M11,"") -> 46029
A12: =IF('Approved-In-Depth'!$A12<>"",'Approved-In-Depth'!A12,"") -> 11 | B12: =IF($O12<>"",$O12,IF($A12<>"",'Approved-In-Depth'!$B12+7,"")) -> 46059 | C12: =IF($A12<>"",'Approved-In-Depth'!C12,"") -> A.K Jeans | D12: =IF($A12<>"",'Approved-In-Depth'!D12,"") -> WholeSale | E12: =IF($A12<>"",'Approved-In-Depth'!E12,"") -> Shop No.79, Al karim Market , New Anarkali ,Lahore | F12: =IF($A12<>"",'Approved-In-Depth'!F12,"") -> Lahore | G12: =IF($A12<>"",'Approved-In-Depth'!G12,"") -> Punjab | H12: =IF($A12<>"",'Approved-In-Depth'!H12,"") -> SafeMark | I12: =IF($A12<>"",'Approved-In-Depth'!I12,"") -> Tommy Hilfiger | J12: =IF($A12<>"",'Approved-In-Depth'!J12,"") -> Jeans | ... M12: =IF($A12<>"",'Approved-In-Depth'!M12,"") -> 46045
A13: =IF('Approved-In-Depth'!$A13<>"",'Approved-In-Depth'!A13,"") -> 12 | B13: =IF($O13<>"",$O13,IF($A13<>"",'Approved-In-Depth'!$B13+7,"")) -> 46052 | C13: =IF($A13<>"",'Approved-In-Depth'!C13,"") -> A.K Jeans | D13: =IF($A13<>"",'Approved-In-Depth'!D13,"") -> WholeSale | E13: =IF($A13<>"",'Approved-In-Depth'!E13,"") -> Shop No.79, Al karim Market , New Anarkali ,Lahore | F13: =IF($A13<>"",'Approved-In-Depth'!F13,"") -> Lahore | G13: =IF($A13<>"",'Approved-In-Depth'!G13,"") -> Punjab | H13: =IF($A13<>"",'Approved-In-Depth'!H13,"") -> SafeMark | I13: =IF($A13<>"",'Approved-In-Depth'!I13,"") -> Levis | J13: =IF($A13<>"",'Approved-In-Depth'!J13,"") -> Jeans | ... M13: =IF($A13<>"",'Approved-In-Depth'!M13,"") -> 46038
... A1000: =IF('Approved-In-Depth'!$A1000<>"",'Approved-In-Depth'!A1000,"") | B1000: =IF($O1000<>"",$O1000,IF($A1000<>"",'Approved-In-Depth'!$B1000+7,"")) | C1000: =IF($A1000<>"",'Approved-In-Depth'!C1000,"") | D1000: =IF($A1000<>"",'Approved-In-Depth'!D1000,"") | E1000: =IF($A1000<>"",'Approved-In-Depth'!E1000,"") | F1000: =IF($A1000<>"",'Approved-In-Depth'!F1000,"") | G1000: =IF($A1000<>"",'Approved-In-Depth'!G1000,"") | H1000: =IF($A1000<>"",'Approved-In-Depth'!H1000,"") | I1000: =IF($A1000<>"",'Approved-In-Depth'!I1000,"") | J1000: =IF($A1000<>"",'Approved-In-Depth'!J1000,"") | ... M1000: =IF($A1000<>"",'Approved-In-Depth'!M1000,"")

Sheet Invoice Due
A1: S.No | B1: Amount | C1: Amount Override | D1: Due Date | E1: Target Name | F1: Target Category | G1: Target Address | H1: City | I1: Provence | J1: Client | K1: Brand Name | L1: Product Name | M1: Case Submission Date | N1: Case Approve Date | O1: In-Depth Date | P1: Enforcement Date | Q1: Remarks | R1: Due Date Override
A2: =IF('Approved-Enforcement'!$A2<>"",'Approved-Enforcement'!A2,"") -> 1 | B2: =IF($A2<>"",IF($C2<>"",$C2,1500),"") -> 1500 | D2: =IF($A2<>"",IF($R2<>"",$R2,'Approved-Enforcement'!$B2+7),"") -> 46024 | E2: =IF($A2<>"",'Approved-Enforcement'!D2,"") -> Shop | F2: =IF($A2<>"",'Approved-Enforcement'!E2,"") -> Godown No. S-19 West Warf, New Lipton Gali ,Karachi | G2: =IF($A2<>"",'Approved-Enforcement'!F2,"") -> Karachi | H2: =IF($A2<>"",'Approved-Enforcement'!G2,"") -> Sindh | I2: =IF($A2<>"",'Approved-Enforcement'!H2,"") -> OneWorld | J2: =IF($A2<>"",'Approved-Enforcement'!I2,"") -> Wd-40 | K2: =IF($A2<>"",'Approved-Enforcement'!J2,"") -> Fluid | L2: =IF($A2<>"",'Approved-Enforcement'!K2,"") -> 45966 | ... P2: =IF($A2<>"",'Approved-Enforcement'!O2,"") -> 0
A3: =IF('Approved-Enforcement'!$A3<>"",'Approved-Enforcement'!A3,"") -> 2 | B3: =IF($A3<>"",IF($C3<>"",$C3,1500),"") -> 1500 | D3: =IF($A3<>"",IF($R3<>"",$R3,'Approved-Enforcement'!$B3+7),"") -> 46056 | E3: =IF($A3<>"",'Approved-Enforcement'!D3,"") -> Factory | F3: =IF($A3<>"",'Approved-Enforcement'!E3,"") -> Plot No.L-27 Sector 12B Industrial Area ,New Karachi | G3: =IF($A3<>"",'Approved-Enforcement'!F3,"") -> Karachi | H3: =IF($A3<>"",'Approved-Enforcement'!G3,"") -> Sindh | I3: =IF($A3<>"",'Approved-Enforcement'!H3,"") -> SafeMark | J3: =IF($A3<>"",'Approved-Enforcement'!I3,"") -> Reebok | K3: =IF($A3<>"",'Approved-Enforcement'!J3,"") -> Garments | L3: =IF($A3<>"",'Approved-Enforcement'!K3,"") -> 46031 | ... P3: =IF($A3<>"",'Approved-Enforcement'!O3,"") -> 0
A4: =IF('Approved-Enforcement'!$A4<>"",'Approved-Enforcement'!A4,"") -> 3 | B4: =IF($A4<>"",IF($C4<>"",$C4,1500),"") -> 1500 | D4: =IF($A4<>"",IF($R4<>"",$R4,'Approved-Enforcement'!$B4+7),"") -> 46056 | E4: =IF($A4<>"",'Approved-Enforcement'!D4,"") -> Factory | F4: =IF($A4<>"",'Approved-Enforcement'!E4,"") -> Plot No.L-27 Sector 12B Industrial Area ,New Karachi | G4: =IF($A4<>"",'Approved-Enforcement'!F4,"") -> Karachi | H4: =IF($A4<>"",'Approved-Enforcement'!G4,"") -> Sindh | I4: =IF($A4<>"",'Approved-Enforcement'!H4,"") -> SafeMark | J4: =IF($A4<>"",'Approved-Enforcement'!I4,"") -> Champion | K4: =IF($A4<>"",'Approved-Enforcement'!J4,"") -> Garments | L4: =IF($A4<>"",'Approved-Enforcement'!K4,"") -> 46031 | ... P4: =IF($A4<>"",'Approved-Enforcement'!O4,"") -> 0
A5: =IF('Approved-Enforcement'!$A5<>"",'Approved-Enforcement'!A5,"") -> 4 | B5: =IF($A5<>"",IF($C5<>"",$C5,1500),"") -> 1500 | D5: =IF($A5<>"",IF($R5<>"",$R5,'Approved-Enforcement'!$B5+7),"") -> 46056 | E5: =IF($A5<>"",'Approved-Enforcement'!D5,"") -> Factory | F5: =IF($A5<>"",'Approved-Enforcement'!E5,"") -> Plot No.L-27 Sector 12B Industrial Area ,New Karachi | G5: =IF($A5<>"",'Approved-Enforcement'!F5,"") -> Karachi | H5: =IF($A5<>"",'Approved-Enforcement'!G5,"") -> Sindh | I5: =IF($A5<>"",'Approved-Enforcement'!H5,"") -> SafeMark | J5: =IF($A5<>"",'Approved-Enforcement'!I5,"") -> Hugo Boss | K5: =IF($A5<>"",'Approved-Enforcement'!J5,"") -> Garments | L5: =IF($A5<>"",'Approved-Enforcement'!K5,"") -> 46031 | ... P5: =IF($A5<>"",'Approved-Enforcement'!O5,"") -> 0
A6: =IF('Approved-Enforcement'!$A6<>"",'Approved-Enforcement'!A6,"") -> 5 | B6: =IF($A6<>"",IF($C6<>"",$C6,1500),"") -> 1500 | D6: =IF($A6<>"",IF($R6<>"",$R6,'Approved-Enforcement'!$B6+7),"") -> 46060 | E6: =IF($A6<>"",'Approved-Enforcement'!D6,"") -> Factory | F6: =IF($A6<>"",'Approved-Enforcement'!E6,"") -> Plot No.C-62 Taksali Androne Lahore | G6: =IF($A6<>"",'Approved-Enforcement'!F6,"") -> Lahore | H6: =IF($A6<>"",'Approved-Enforcement'!G6,"") -> Punjab | I6: =IF($A6<>"",'Approved-Enforcement'!H6,"") -> SafeMark | J6: =IF($A6<>"",'Approved-Enforcement'!I6,"") -> Tommy Hilfiger | K6: =IF($A6<>"",'Approved-Enforcement'!J6,"") -> Shoes | L6: =IF($A6<>"",'Approved-Enforcement'!K6,"") -> 46031 | ... P6: =IF($A6<>"",'Approved-Enforcement'!O6,"") -> 0
